Workbook

Sheet Read me
A1: FJUH drug database: discrepancies with official labels
A3: Prepared | B3: 2026-10-05, while verifying the pharmacy antimicrobial reference (Notion) against official sources.
A4: Scope | B4: 1464 items found while checking 91 hospital antimicrobials on 2026-10-05 and 2026-10-06 (pharmacy.fjuh.fju.edu.tw).
A5: Sources | B5: US FDA label (DailyMed), UK SmPC (medicines.org.uk), Taiwan package insert (TFDA / hospital-hosted PDFs), NIH LactMed, IDSA and other guidelines. Each row cites its source.
A6: Severity | B6: High = could cause harm if followed (wrong or missing dose adjustment, missing contraindication or boxed warning). Medium = clinically relevant omission or outdated content. Low = wording, retired FDA letter categories, pharmacokinetic detail.
A7: Caution | B7: Severity and suggested actions were drafted with AI assistance from the label comparison and have not yet been reviewed by a pharmacist. Please confirm each item against the cited source before changing the database.
A8: How to use | B8: Start with the "High priority" tab. Track progress in the "DI team status" and "DI team notes" columns. "Recurring patterns" lists issues that repeat across drugs and can be fixed in one batch.
A10: Counts
A11: High | B11: =COUNTIF('All issues'!$C$2:$C$1465,"High")
A12: Medium | B12: =COUNTIF('All issues'!$C$2:$C$1465,"Medium")
A13: Low | B13: =COUNTIF('All issues'!$C$2:$C$1465,"Low")
A14: Total | B14: =SUM(B11:B13)

Sheet High priority
A1: ID | B1: Drug (hospital code) | C1: Severity | D1: Category | E1: Recurring pattern | F1: Suggested action | G1: Hospital database says | H1: Official source says | I1: Source | J1: DI team status | K1: DI team notes
A2: 1200 | B2: Akurit-4 / Akurit-3 (TB fixed-dose combinations) (AKU02, AKU01) | C2: High | D2: Contraindication/warning | F2: Add Akurit-3 contraindications: severe hepatic impairment, acute liver disease, acute gout. | G2: Lists hypersensitivity, ART, previous INH hepatic injury, severe INH reactions and optic neuritis only | H2: The Akurit-3 insert also contraindicates severe hepatic impairment, acute liver disease of any cause and acute gout | I2: TW 仿單 Akurit-3 §4 禁忌 — https://mcp.fda.gov.tw/im_detail_1/%E8%A1%9B%E7%BD%B2%E8%97%A5%E8%BC%B8%E5%AD%97%E7%AC%AC025519%E8%99%9F | J2: Open
A3: 1203 | B3: Akurit-4 / Akurit-3 (TB fixed-dose combinations) (AKU02, AKU01) | C3: High | D3: Dosing – adult | F3: Add caveat to >70 kg 5-tablet dose: 'may consider', follow TW CDC guideline, INH 300/RIF 600 mg caps. | G3: Body weight >70 kg: 5 tab PO QD | H3: The insert says ≥71 kg 5 tablets 「可考慮」 and to follow the TW CDC 結核病診治指引, which caps INH at 300 mg and RIF at 600 mg. Five tablets give RIF 750 and INH 375 mg, over that cap, and the hospital page drops the caveat. | I3: TW 仿單 Akurit-4/Akurit-3 §3.1 — https://mcp.fda.gov.tw/im_detail_1/%E8%A1%9B%E7%BD%B2%E8%97%A5%E8%BC%B8%E5%AD%97%E7%AC%AC025518%E8%99%9F | J3: Open
A4: 1211 | B4: Akurit-4 / Akurit-3 (TB fixed-dose combinations) (AKU02, AKU01) | C4: High | D4: Dosing – adult | F4: Add caveat to 5-tablet >70 kg dose: exceeds INH 300/RIF 600 mg max; follow TW CDC guideline. | G4: Body weight >70 kg: 5 tab PO QD, with no caveat. | H4: The 仿單 says ≥71 kg 5 tablets 「可考慮」, but refers dosing to the 疾管署結核病診治指引 and states the daily maximum of INH 300 mg and RIF 600 mg. 5 tablets delivers RIF 750 mg and INH 375 mg. | I4: Akurit-4/Akurit-3 仿單 §3.1 https://mcp.fda.gov.tw/im_detail_1/%E8%A1%9B%E7%BD%B2%E8%97%A5%E8%BC%B8%E5%AD%97%E7%AC%AC025518%E8%99%9F | J4: Open
A5: 1204 | B5: Akurit-4 / Akurit-3 (TB fixed-dose combinations) (AKU02, AKU01) | C5: High | D5: Dosing – renal/dialysis | F5: Fill renal/hepatic fields: FDC unsuitable at CrCl<30/HD (EMB adjustment); contraindicated in acute liver disease. | G5: AKU01: renal field blank, and the adjacent hepatic field reads 'There are no dosage adjustments provided in the manufacturer's labeling; use with caution.' AKU02: both renal and hepatic fields are blank. | H5: Both inserts state that ethambutol must be reduced by serum level in renal impairment, so the fixed tablet is unsuitable at CrCl <30 or on HD. They also contraindicate acute liver disease, and Akurit-3 contraindicates severe hepatic impairment. | I5: TW 仿單 Akurit-3 §5.1 Ethambutol and §4 — https://mcp.fda.gov.tw/im_detail_1/%E8%A1%9B%E7%BD%B2%E8%97%A5%E8%BC%B8%E5%AD%97%E7%AC%AC025519%E8%99%9F; US ethambutol label PRECAUTIONS | J5: Open
A6: 1212 | B6: Akurit-4 / Akurit-3 (TB fixed-dose combinations) (AKU02, AKU01) | C6: High | D6: Dosing – renal/dialysis | F6: State FDC unsuitable for CrCl<30/HD; use single agents thrice weekly; add severe hepatic impairment contraindication. | G6: AKU01: 'There are no dosage adjustments provided in the manufacturer's labeling; use with caution.' AKU02: renal field empty. | H6: Both inserts §5.1 say ethambutol must be reduced according to serum levels in renal impairment. The FDC cannot be adjusted, so CrCl <30 or HD needs single agents (UK EMB SmPC §4.2: 15–25 mg/kg 3×/week; ATS 2016: PZA/EMB thrice weekly after HD). The Akurit-3 insert also contraindicates use in severe hepatic impairment. | I6: Akurit-3 仿單 §4, §5.1 https://mcp.fda.gov.tw/im_detail_1/%E8%A1%9B%E7%BD%B2%E8%97%A5%E8%BC%B8%E5%AD%97%E7%AC%AC025519%E8%99%9F ; UK Ethambutol SmPC §4.2 https://www.medicines.org.uk/emc/product/14174/smpc | J6: Open
A7: 1199 | B7: Akurit-4 / Akurit-3 (TB fixed-dose combinations) (AKU02, AKU01) | C7: High | D7: Drug interaction | E7: Interaction list incomplete | F7: Add contraindicated fosamprenavir, cabotegravir, fostemsavir, lenacapavir, praziquantel, lurasidone; cite ARV label source for rilpivirine/EVG. | G7: Concomitant atazanavir, darunavir, saquinavir, tipranavir, rilpivirine or elvitegravir/cobicistat | H7: The US rifampin label contraindicates atazanavir, darunavir, fosamprenavir, saquinavir, tipranavir, ritonavir-boosted saquinavir, cabotegravir, fostemsavir, lenacapavir (Sunlenca), praziquantel and lurasidone. UK SmPC adds sofosbuvir, daclatasvir, telaprevir and jaundice. The hospital list leaves out fosamprenavir, cabotegravir, fostemsavir, lenacapavir, praziquantel and lurasidone. Rilpivirine and EVG/c are not in the rifampin label, although their own labels contraindicate rifampin. | I7: US rifampin label CONTRAINDICATIONS — https://dailymed.nlm.nih.gov/dailymed/drugInfo.cfm?setid=50f706f9-5003-4e15-bece-85b6213b1f5c; UK Rifater SmPC 4.3 — https://www.medicines.org.uk/emc/product/1596/smpc | J7: Open
A8: 1208 | B8: Akurit-4 / Akurit-3 (TB fixed-dose combinations) (AKU02, AKU01) | C8: High | D8: Drug interaction | E8: Interaction list incomplete | F8: Expand rifampin contraindicated list with fosamprenavir, cabotegravir, fostemsavir, lenacapavir, praziquantel, lurasidone, sofosbuvir etc. | G8: Lists concomitant atazanavir, darunavir, saquinavir, tipranavir, rilpivirine or elvitegravir/cobicistat. | H8: The list is incomplete compared with the rifampin labels. The US label also contraindicates fosamprenavir, cabotegravir, fostemsavir, lenacapavir, praziquantel and lurasidone, plus saquinavir/ritonavir for hepatotoxicity. The UK Rifater SmPC adds sofosbuvir, daclatasvir and telaprevir. Rilpivirine and elvitegravir/cobicistat are not in the rifampin label contraindications (they come from the ARV labels). | I8: US rifampin label, Contraindications https://dailymed.nlm.nih.gov/dailymed/drugInfo.cfm?setid=50f706f9-5003-4e15-bece-85b6213b1f5c ; UK Rifater SmPC §4.3 https://www.medicines.org.uk/emc/product/1596/smpc | J8: Open
A9: 223 | B9: Amikacin (AMI12) | C9: High | D9: Dosing – adult | F9: State label max 15 mg/kg/day (≤1.5 g/day); mark higher/intrathecal regimens off-label with citations | G9: Bloodstream infection IV 15–30 mg/kg once daily; CF 30–35 mg/kg once daily; intraventricular/intrathecal 5–50 mg/day; other off-label regimens | H9: US: total daily dose ≤15 mg/kg/day in 2–3 doses; heavy patients ≤1.5 g/day. UK: 15 mg/kg/day (once daily only if CrCl ≥50), ≤1.5 g/day. TW (stocked product): 7.5–15 mg/kg/day ÷2, ≤1.5 g/day. No label gives an intrathecal dose; the UK SmPC mentions only 0.25% irrigation of the cerebral ventricles. | I9: US D&A; UK SmPC 4.2; Taiwan insert 3.1 – https://mcp.fda.gov.tw/im_detail_1/%E8%A1%9B%E7%BD%B2%E8%97%A5%E8%A3%BD%E5%AD%97%E7%AC%AC024198%E8%99%9F | J9: Open
A10: 229 | B10: Amikacin (AMI12) | C10: High | D10: Dosing – adult | F10: Cap at label 15 mg/kg/day; mark 15–35 mg/kg regimens off-label with citations | G10: Bloodstream infection, and sepsis/septic shock: IV 15 to 30 mg/kg once daily. HAP/VAP and plague: 15–20 mg/kg once daily. CF: 30–35 mg/kg once daily. | H10: US: total daily dose must not exceed 15 mg/kg/day, and heavier patients ≤1.5 g/day. UK: 15 mg/kg/day, ≤1.5 g/day. TW insert: 7.5–15 mg/kg/day ÷ bid; life-threatening or Pseudomonas up to 500 mg q8h, ≤1.5 g/day. Doses above this are off-label and need a guideline or PubMed source (e.g. Taccone 2010, PMID 20370907, for ≥25 mg/kg in septic shock). | I10: US label DOSAGE AND ADMINISTRATION; UK SmPC 4.2; TW insert 3.1, https://mcp.fda.gov.tw/im_detail_1/%E8%A1%9B%E7%BD%B2%E8%97%A5%E8%A3%BD%E5%AD%97%E7%AC%AC024198%E8%99%9F | J10: Open
A11: 231 | B11: Amikacin (AMI12) | C11: High | D11: Dosing – adult | F11: Add limits: high-dose 500 mg q8h max 1.5 g/day, ≤10 days, total course ≤15 g (TW/UK); reassess beyond 10 days | G11: No maximum daily dose, treatment duration, or total-course limit stated. | H11: TW insert 3.1 and UK SmPC 4.2: escalated regimen (500 mg q8h) ≤1.5 g/day, ≤10 days, total ≤15 g. US: usual 7–10 days; reassess if >10 days; safety >14 days not established. | I11: TW insert 3.1; UK SmPC 4.2; US label DOSAGE AND ADMINISTRATION and WARNINGS box | J11: Open
A12: 224 | B12: Amikacin (AMI12) | C12: High | D12: Dosing – renal/dialysis | E12: Renal table outdated | F12: Replace unsourced GFR/CRRT table with label method or cite source; reconcile CRRT with Notion | G12: GFR 30–50: 5–7.5 mg/kg q12–18h; GFR 10–29: q18–24h; GFR <10: q48–72h; HD/PD 5 mg/kg then redose by level; CRRT 7.5 mg/kg q12h | H12: No label has GFR tiers or CRRT dosing. US: 7.5 mg/kg every (SCr × 9) h, or 7.5 mg/kg LD then reduced q12h dose in proportion to CrCl; neither method during dialysis. UK: same methods, and no once-daily total dose if CrCl <50. TW insert: no renal table. The hospital CRRT dose (7.5 mg/kg q12h) also disagrees with the Notion CRRT entry (LD 10 mg/kg then TDM). Both need a guideline or PubMed source. | I12: US D&A renal sections – https://dailymed.nlm.nih.gov/dailymed/drugInfo.cfm?setid=f260ff2a-76a0-4672-9516-91c344b67890; UK SmPC 4.2 | J12: Open
A13: 230 | B13: Amikacin (AMI12) | C13: High | D13: Dosing – renal/dialysis | E13: Renal table outdated | F13: Replace pediatric-unit GFR table with adult label renal method; CRRT per evidence with TDM | G13: GFR 30–50 mL/min/1.73 m²: 5–7.5 mg/kg q12–18h; GFR 10–29: q18–24h; GFR <10: q48–72h; IHD 5 mg/kg, redose by level; CRRT 7.5 mg/kg q12h. This sits right after the paediatric section, and the units (per 1.73 m²) suggest a paediatric table shown as the general renal adjustment. | H13: No label gives GFR tiers or CRRT dosing. US label (fallback, since the TW insert has none): 7.5 mg/kg every SCr×9 h, or a 7.5 mg/kg loading dose then reduced q12h doses in proportion to CrCl; neither method during dialysis. UK SmPC: no once-daily dosing if CrCl <50. CRRT evidence (Roger 2016, PMID 27270279) supports 25 mg/kg about q48h with TDM, not 7.5 mg/kg q12h. | I13: US label Impaired Renal Function sections; UK SmPC 4.2; Roger C 2016, https://pubmed.ncbi.nlm.nih.gov/27270279/ | J13: Open
A14: 235 | B14: AmoClav (Amoxicillin/clavulanate) (AMO04, AMO08) | C14: High | D14: Dosing – adult | F14: Remove q6h option: 1.2 g q8h only (max 600 mg clavulanate/day); use other IV amoxicillin if more needed | G14: 1.2 g every 8 hours; in severe infections, administer every 6 hours | H14: 1000 mg/200 mg every 8 hours only. This product delivers at most 3000 mg amoxicillin + 600 mg clavulanate a day; if more amoxicillin is needed, use an alternative IV formulation. q6h would give 800 mg/day clavulanate. | I14: UK SmPC 4.2 — https://www.medicines.org.uk/emc/product/7211/smpc | J14: Open
A15: 236 | B15: AmoClav (Amoxicillin/clavulanate) (AMO04, AMO08) | C15: High | D15: Dosing – adult | F15: Fix prophylaxis: <1 h single 1.2–2.2 g at induction; >1 h up to 3 doses total in 24 h | G15: 1.2 g at induction of anesthesia for procedures 1 hour, may administer up to 2-3 additional doses in 24 hours (the < or > sign is missing) | H15: Procedures <1 h: 1000/200 to 2000/200 mg at induction. Procedures >1 h: same at induction, with up to 3 doses of 1000/200 mg in 24 hours (3 in total, not 2–3 additional). | I15: UK SmPC 4.2 — https://www.medicines.org.uk/emc/product/7211/smpc | J15: Open
A16: 246 | B16: AmoClav (Amoxicillin/clavulanate) (AMO04, AMO08) | C16: High | D16: Dosing – adult | F16: Remove q6h option: 1.2 g q8h only (max 600 mg clavulanate/day) | G16: 1.2 g every 8 hours; in severe infections, administer every 6 hours | H16: 1000/200 mg every 8 hours only. The vial is designed for at most 3000 mg amoxicillin + 600 mg clavulanate a day (q6h gives 800 mg clavulanate). If more amoxicillin is needed, use an alternative IV formulation. | I16: UK SmPC §4.2, https://www.medicines.org.uk/emc/product/7211/smpc | J16: Open
A17: 247 | B17: AmoClav (Amoxicillin/clavulanate) (AMO04, AMO08) | C17: High | D17: Dosing – adult | F17: Restore '<'/'>' and state max 3 doses total in 24 h for procedures >1 h | G17: 1.2 g at induction of anesthesia for procedures [sign missing] 1 hour, may administer up to 2-3 additional doses in 24 hours | H17: Procedures <1 h: 1000/200–2000/200 mg at induction. Procedures >1 h: same, with up to 3 doses of 1000/200 mg in 24 h in total. The '<'/'>' sign is lost in the hospital text, and '2-3 additional doses' could exceed 3 doses in total. | I17: UK SmPC §4.2, https://www.medicines.org.uk/emc/product/7211/smpc | J17: Open
A18: 237 | B18: AmoClav (Amoxicillin/clavulanate) (AMO04, AMO08) | C18: High | D18: Dosing – pediatric | F18: Pediatric <40 kg: ≥3 mo 30 mg/kg q8h; <3 mo or <4 kg 30 mg/kg q12h infusion; remove q6h and titration | G18: 3 months to 12 years: 30 mg/kg every 8 hours; in severe infections, administer every 6 hours. 30 mg/kg every 12 hours; then titrate to every 8 hours (no age/weight condition). | H18: Children <40 kg (weight-based, not 'to 12 years'): ≥3 months 25/5 mg/kg (30 mg/kg combined) q8h. Children <3 months or <4 kg: 25/5 mg/kg q12h, infusion only. There is no q6h option and no 'titrate to q8h' step. The pediatric q6h-in-severe-infection line was not in the source brief; I found it on the live page. | I18: UK SmPC 4.2 Paediatric population — https://www.medicines.org.uk/emc/product/7211/smpc | J18: Open
A19: 248 | B19: AmoClav (Amoxicillin/clavulanate) (AMO04, AMO08) | C19: High | D19: Dosing – pediatric | F19: Weight-based <40 kg dosing; no q6h; q12h only for <3 mo or <4 kg by infusion | G19: 3 months to 12 years: 30 mg/kg every 8 hours; in severe infections every 6 hours / 30 mg/kg every 12 hours; then titrate to every 8 hours | H19: Children <40 kg: ≥3 months, 25/5 mg/kg (=30 mg/kg combined) q8h; <3 months or <4 kg, 25/5 mg/kg q12h by infusion only. No q6h regimen. The q12h line in the hospital entry has no age or weight condition, and the limit is weight-based (<40 kg), not 12 years. | I19: UK SmPC §4.2 Paediatric population and Method of administration, https://www.medicines.org.uk/emc/product/7211/smpc | J19: Open
A20: 238 | B20: AmoClav (Amoxicillin/clavulanate) (AMO04, AMO08) | C20: High | D20: Dosing – renal/dialysis | E20: Renal table outdated | F20: HD: 1.2 g once, then 600 mg q24h plus 600 mg after dialysis; remove q12h option; use combined units | G20: 1 g followed by 500 mg every 12 to 24 hours; if utilizing a 24-hour interval, administer dose after dialysis or give an additional 500 mg after dialysis (units switch from 1.2 g product to amoxicillin-only mg) | H20: 1000/200 mg (1.2 g) initially, then 500/100 mg (600 mg) every 24 h, plus 500/100 mg at the end of dialysis. No q12h option. | I20: UK SmPC 4.2 Renal impairment — https://www.medicines.org.uk/emc/product/7211/smpc | J20: Open
A21: 239 | B21: AmoClav (Amoxicillin/clavulanate) (AMO04, AMO08) | C21: High | D21: Dosing – renal/dialysis | E21: Renal table outdated | F21: Remove unsupported PD q12h regimen; no label PD dose (CrCl <10 maintenance is 600 mg q24h) | G21: 1 g followed by 500 mg every 12 hours | H21: No peritoneal dialysis dose in the UK SmPC or US label. For CrCl <10 the SmPC gives 600 mg q24h maintenance, so a q12h PD regimen is unsupported. | I21: UK SmPC 4.2 — https://www.medicines.org.uk/emc/product/7211/smpc; US label 2.6 — https://dailymed.nlm.nih.gov/dailymed/drugInfo.cfm?setid=80bef3fd-4f6f-4190-8865-9ac46c8947a3 | J21: Open
A22: 240 | B22: AmoClav (Amoxicillin/clavulanate) (AMO04, AMO08) | C22: High | D22: Dosing – renal/dialysis | F22: Escape '<' in HTML so CrCl <10 band (1.2 g then 600 mg q24h) displays | G22: Rendered page shows only '3. CrCl' followed by '4. Hemodialysis'. The unescaped '<' cuts the text off; it reads in full only in the raw source ('CrCl <10 mL/min: 1.2 g followed by 600 mg every 24 hours'). | H22: The dose itself matches the SmPC (1.2 g, then 600 mg q24h). The defect is HTML escaping: the CrCl <10 line is invisible to users. | I22: UK SmPC 4.2 — https://www.medicines.org.uk/emc/product/7211/smpc | J22: Open
A23: 249 | B23: AmoClav (Amoxicillin/clavulanate) (AMO04, AMO08) | C23: High | D23: Dosing – renal/dialysis | E23: Renal table outdated | F23: HD: 1.2 g once, then 600 mg q24h plus 600 mg after dialysis; no q12h | G23: 1 g followed by 500 mg every 12 to 24 hours; if 24-hour interval, dose after dialysis or extra 500 mg after dialysis | H23: 1000/200 mg once, then 500/100 mg every 24 h, plus 500/100 mg at the end of dialysis. Units should be 1.2 g/600 mg to match the combined-strength convention used elsewhere. The SmPC gives no q12h option for HD. | I23: UK SmPC §4.2 Renal impairment, https://www.medicines.org.uk/emc/product/7211/smpc | J23: Open
A24: 250 | B24: AmoClav (Amoxicillin/clavulanate) (AMO04, AMO08) | C24: High | D24: Dosing – renal/dialysis | E24: Renal table outdated | F24: Remove PD 500 mg q12h regimen; no label support | G24: 1 g followed by 500 mg every 12 hours | H24: No PD regimen in the UK SmPC or the US label | I24: UK SmPC §4.2, https://www.medicines.org.uk/emc/product/7211/smpc | J24: Open
A25: 251 | B25: AmoClav (Amoxicillin/clavulanate) (AMO04, AMO08) | C25: High | D25: Dosing – renal/dialysis | F25: Escape '<' as &lt; so CrCl <10 line renders | G25: Rendered page shows '3. CrCl' with the text cut off. The raw HTML has 'CrCl <10 mL/min: 1.2 g followed by 600 mg every 24 hours'; the unescaped '<' breaks rendering. | H25: CrCl <10: 1000/200 mg once, then 500/100 mg q24h (the content is correct once shown; the HTML needs '&lt;') | I25: UK SmPC §4.2, https://www.medicines.org.uk/emc/product/7211/smpc | J25: Open
A26: 581 | B26: Amoxicillin (AMO02) | C26: High | D26: Dosing – renal/dialysis | E26: Renal table outdated | F26: Restore GFR <10 label; set 250-500 mg q24h (US), max 500 mg/day (UK); remove q12h | G26: The row after '10-30' has no GFR label: '250 to 500 mg every 12 to 24 hours / 500 mg every 12 to 24 hours / 500 mg every 12 hours'. | H26: Presumably this row is GFR <10, and the US label gives 250–500 mg q24h there, not q12–24h. The UK SmPC gives a maximum of 500 mg/day. Neither label supports the 'every 12 hours' column. | I26: US FDA label §2.5 Table 2 — https://dailymed.nlm.nih.gov/dailymed/drugInfo.cfm?setid=9b3ab9ea-caee-4186-9068-43ca527c098d; UK SmPC §4.2 — https://www.medicines.org.uk/emc/product/10637/smpc | J26: Open
A27: 582 | B27: Amoxicillin (AMO02) | C27: High | D27: Dosing – renal/dialysis | E27: Renal table outdated | F27: GFR 10-30: change 1 g q12h to 250-500 mg q12h (max 500 mg bid) | G27: 1 g every 12 hours | H27: US: 250–500 mg every 12 hours. UK: maximum 500 mg twice daily. 1 g q12h is twice the labelled maximum. | I27: US FDA label §2.5 Table 2 — https://dailymed.nlm.nih.gov/dailymed/drugInfo.cfm?setid=9b3ab9ea-caee-4186-9068-43ca527c098d; UK SmPC §4.2 Renal impairment — https://www.medicines.org.uk/emc/product/10637/smpc | J27: Open
A28: 583 | B28: Amoxicillin (AMO02) | C28: High | D28: Dosing – renal/dialysis | E28: Renal table outdated | F28: HD: 250-500 mg q24h plus supplemental dose during/after HD; remove q12h options | G28: 250 to 500 mg every 12 to 24 hours / 500 mg every 12 to 24 hours / 500 mg every 12 hours | H28: US: 250–500 mg every 24 h, plus an extra dose during and at the end of dialysis. UK: 500 mg every 24 h, plus 500 mg before and 500 mg after HD. Neither label has a q12h option, and the hospital row omits the supplemental dose. The source brief did not mention this discrepancy. | I28: US FDA label §2.5 — https://dailymed.nlm.nih.gov/dailymed/drugInfo.cfm?setid=9b3ab9ea-caee-4186-9068-43ca527c098d; UK SmPC §4.2 Haemodialysis — https://www.medicines.org.uk/emc/product/10637/smpc | J28: Open
A29: 584 | B29: Amoxicillin (AMO02) | C29: High | D29: Dosing – renal/dialysis | E29: Renal table outdated | F29: PD: cap at 500 mg/day (UK SmPC); remove 500 mg q12h | G29: 250 to 500 mg every 12 hours / 500 mg every 12 hours / 500 mg every 12 hours | H29: UK: maximum 500 mg/day. The US label has no PD dose, so the PD row conflicts with the UK SmPC only; 500 mg q12h is 1 g/day. | I29: UK SmPC §4.2 'In patients receiving peritoneal dialysis Amoxicillin maximum 500 mg/day' — https://www.medicines.org.uk/emc/product/10637/smpc | J29: Open
A30: 591 | B30: Amoxicillin (AMO02) | C30: High | D30: Dosing – renal/dialysis | E30: Renal table outdated | F30: Fix missing '<10' row label (HTML escape); set 250-500 mg q24h, max 500 mg/day | G30: Row with no GFR label: '250 to 500 mg every 12 to 24 hours / 500 mg every 12 to 24 hours / 500 mg every 12 hours' (presumably GFR <10; label probably lost to unescaped '<' in HTML) | H30: GFR <10: 250–500 mg q24h (US); max 500 mg/day (UK). q12h and q12–24h both exceed the label maximum. | I30: US label §2.5 Table 2 — https://dailymed.nlm.nih.gov/dailymed/drugInfo.cfm?setid=9b3ab9ea-caee-4186-9068-43ca527c098d; UK SmPC §4.2 — https://www.medicines.org.uk/emc/product/10637/smpc | J30: Open
A31: 592 | B31: Amoxicillin (AMO02) | C31: High | D31: Dosing – renal/dialysis | E31: Renal table outdated | F31: GFR 10-30: change 1 g q12h to 250-500 mg q12h | G31: 1 g every 12 hours | H31: US: 250–500 mg q12h; UK: maximum 500 mg twice daily | I31: US label §2.5 Table 2; UK SmPC §4.2 renal table | J31: Open
A32: 593 | B32: Amoxicillin (AMO02) | C32: High | D32: Dosing – renal/dialysis | E32: Renal table outdated | F32: HD: 250-500 mg q24h plus supplemental dose with HD; remove q12h | G32: 250–500 mg q12–24h / 500 mg q12–24h / 500 mg q12h; no supplemental dose | H32: US: 250–500 mg q24h + extra dose during and at end of HD. UK: 500 mg q24h + 500 mg before and 500 mg after HD. No q12h option. | I32: US label §2.5 Table 2; UK SmPC §4.2 haemodialysis | J32: Open
A33: 594 | B33: Amoxicillin (AMO02) | C33: High | D33: Dosing – renal/dialysis | E33: Renal table outdated | F33: PD: max 500 mg/day (UK SmPC); remove q12h regimens | G33: 250–500 mg q12h / 500 mg q12h / 500 mg q12h (up to 1 g/day) | H33: UK: maximum 500 mg/day. No US PD dose. | I33: UK SmPC §4.2 peritoneal dialysis — https://www.medicines.org.uk/emc/product/10637/smpc | J33: Open
A34: 576 | B34: Ampolin (Ampicillin) (AMP01) | C34: High | D34: Dosing – adult | F34: Add label doses; label 2 g q4h and 300-400 mg/kg/day as guideline with citation; 400 mg/kg/day exceeds labels | G34: Adults 2 g q4h (enterococcal/Listeria bacteremia, endocarditis, meningitis); 1–2 g q4–6h for enterococcal cUTI; children 50–200 mg/kg/day (max 8 g/day), 300–400 mg/kg/day (max 12 g/day) for meningitis/endocarditis. No citation, and no label doses shown. | H34: The stocked product's insert gives 250–500 mg q6h (or 2–4×/day IM), gonococcal urethritis 500 mg q12h, meningitis 8–14 g/day adults and 100–200 mg/kg/day children. US: 250–500 mg q6h; meningitis/septicemia 150–200 mg/kg/day q3–4h. UK: 500 mg 4–6×/day; meningitis 2 g q6h. The 2 g q4h and 300–400 mg/kg/day regimens are guideline (IDSA/AHA/ESC) doses, not label doses, and should be labelled and cited as such. 400 mg/kg/day exceeds every label. | I34: Ampolin 仿單 用法用量 https://mcp.fda.gov.tw/insert/pdfcasefile/i_f87fe441-fe10-4930-90d7-250bb0fcbf57; DailyMed DOSAGE AND ADMINISTRATION https://dailymed.nlm.nih.gov/dailymed/drugInfo.cfm?setid=64a04e8c-8f78-46b3-8f45-56ef225a4f74; UK SmPC 4.2 https://www.medicines.org.uk/emc/product/12892/smpc | J34: Open
A35: 568 | B35: Ampolin (Ampicillin) (AMP01) | C35: High | D35: Dosing – pediatric | F35: Clarify cIAI max 2,000 mg as per dose; note no label cIAI pediatric dose | G35: 200 mg/kg/day divided every 6 hours; maximum 2,000 mg | H35: No label gives a paediatric cIAI dose. 'Maximum 2,000 mg' does not say whether it is per dose or per day; read as per day it caps a 200 mg/kg/day regimen at 10 kg body weight. It looks like a per-dose cap written ambiguously. The label paediatric doses are 25-50 mg/kg/day (RTI/soft tissue), 50 mg/kg/day (GI/GU) and 150-200 mg/kg/day (meningitis/septicemia). | I35: DailyMed ampicillin DOSAGE AND ADMINISTRATION https://dailymed.nlm.nih.gov/dailymed/drugInfo.cfm?setid=3b683547-48ac-48ca-8fd4-6866fd17be34 | J35: Open
A36: 569 | B36: Ampolin (Ampicillin) (AMP01) | C36: High | D36: Dosing – pediatric | F36: Replace pediatric doses with label ranges; add US neonatal GA/PNA table; flag >200 mg/kg/day as off-label | G36: 50-200 mg/kg/day q6h (max 8 g/day); 300-400 mg/kg/day (max 12 g/day) for meningitis; IE 200-300 mg/kg/day | H36: These figures and maximums are not in the TW insert (meningitis 100-200 mg/kg/day; general 25-60 mg/kg/day) or the US label (150-200 mg/kg/day; neonatal table by GA/PNA). The neonatal dosing table in the US label is missing from the hospital page. | I36: Taiwan insert https://mcp.fda.gov.tw/insert/pdfcasefile/i_f87fe441-fe10-4930-90d7-250bb0fcbf57; DailyMed ampicillin TABLE 1 https://dailymed.nlm.nih.gov/dailymed/drugInfo.cfm?setid=3b683547-48ac-48ca-8fd4-6866fd17be34 | J36: Open
A37: 575 | B37: Ampolin (Ampicillin) (AMP01) | C37: High | D37: Dosing – pediatric | F37: Specify cIAI cap as 2,000 mg/dose; note not label-derived | G37: 200 mg/kg/day divided every 6 hours; maximum 2,000 mg | H37: No label gives a pediatric cIAI dose or this cap. As written, 'maximum 2,000 mg' reads as a daily cap, which would contradict 200 mg/kg/day for any child over 10 kg. It is presumably a per-dose cap and should say '/dose'. | I37: DailyMed ampicillin DOSAGE AND ADMINISTRATION (no cIAI dose) https://dailymed.nlm.nih.gov/dailymed/drugInfo.cfm?setid=3b683547-48ac-48ca-8fd4-6866fd17be34; Ampolin 仿單 https://mcp.fda.gov.tw/insert/pdfcasefile/i_f87fe441-fe10-4930-90d7-250bb0fcbf57 | J37: Open
A38: 570 | B38: Ampolin (Ampicillin) (AMP01) | C38: High | D38: Dosing – renal/dialysis | E38: Renal table outdated | F38: Cite renal intervals source; add post-HD supplemental dose (UK SmPC) | G38: CrCl 10-50: interval q6-12h; CrCl <10: interval q12-16h | H38: The TW insert and US labels have no CrCl table. The UK SmPC says only that for CrCl <10 the dose should be reduced or the interval extended, with an extra dose after dialysis. The hospital's intervals cite no source, and the page says nothing about dosing after HD. | I38: UK SmPC 4.2 https://www.medicines.org.uk/emc/product/12892/smpc; DailyMed ampicillin OVERDOSAGE https://dailymed.nlm.nih.gov/dailymed/drugInfo.cfm?setid=3b683547-48ac-48ca-8fd4-6866fd17be34 | J38: Open
A39: 577 | B39: Ampolin (Ampicillin) (AMP01) | C39: High | D39: Dosing – renal/dialysis | E39: Renal table outdated | F39: Revise renal intervals (q12h CrCl 7-30, q24h post-HD in ESRD per Blum 1989); add HD/PD/CRRT guidance with sources | G39: CrCl 10–50: q6–12h; CrCl <10: q12–16h (uncited) | H39: No label has a CrCl table: the TW insert has no renal section, the US label has none, and the UK SmPC only says CrCl <10 → reduce dose or extend interval plus a post-dialysis dose. The available PK study (Blum 1989, ampicillin 2 g) supports q12h at CrCl 7–30 and q24h after HD for ESRD, longer than the hospital's q12–16h. The hospital page also gives no HD, PD or CRRT guidance. The label says ampicillin is removed by HD, not PD. | I39: UK SmPC 4.2 Renal Impairment https://www.medicines.org.uk/emc/product/12892/smpc; DailyMed OVERDOSAGE https://dailymed.nlm.nih.gov/dailymed/drugInfo.cfm?setid=3b683547-48ac-48ca-8fd4-6866fd17be34; Blum RA 1989 PMID 2817847 https://pubmed.ncbi.nlm.nih.gov/2817847/ | J39: Open
A40: 269 | B40: Antifect (Cefepime) (ANT10) | C40: High | D40: Administration/compatibility | F40: Infusion fluids: NS, D5W/D10W, D5NS, M/6 lactate, LR with D5; SWFI for reconstitution only, not plain LR | G40: 稀釋溶液：NS、D5W、SWFI、LR (仿單) | H40: TW insert/FDA infusion fluids: 0.9% NaCl, 5% and 10% dextrose, M/6 sodium lactate, D5NS, lactated Ringer's WITH 5% dextrose (not plain LR). Sterile water is listed only for reconstitution, not as an infusion diluent. | I40: Taiwan Antifect insert §3.2 相容性及安定性 — https://mcp.fda.gov.tw/im_detail_1/%E8%A1%9B%E7%BD%B2%E8%97%A5%E8%A3%BD%E5%AD%97%E7%AC%AC047983%E8%99%9F ; US FDA label §2.4, §2.6 | J40: Open
...

Sheet All issues
A1: ID | B1: Drug (hospital code) | C1: Severity | D1: Category | E1: Recurring pattern | F1: Suggested action | G1: Hospital database says | H1: Official source says | I1: Source | J1: DI team status | K1: DI team notes
A2: 1200 | B2: Akurit-4 / Akurit-3 (TB fixed-dose combinations) (AKU02, AKU01) | C2: High | D2: Contraindication/warning | F2: Add Akurit-3 contraindications: severe hepatic impairment, acute liver disease, acute gout. | G2: Lists hypersensitivity, ART, previous INH hepatic injury, severe INH reactions and optic neuritis only | H2: The Akurit-3 insert also contraindicates severe hepatic impairment, acute liver disease of any cause and acute gout | I2: TW 仿單 Akurit-3 §4 禁忌 — https://mcp.fda.gov.tw/im_detail_1/%E8%A1%9B%E7%BD%B2%E8%97%A5%E8%BC%B8%E5%AD%97%E7%AC%AC025519%E8%99%9F | J2: Open
A3: 1203 | B3: Akurit-4 / Akurit-3 (TB fixed-dose combinations) (AKU02, AKU01) | C3: High | D3: Dosing – adult | F3: Add caveat to >70 kg 5-tablet dose: 'may consider', follow TW CDC guideline, INH 300/RIF 600 mg caps. | G3: Body weight >70 kg: 5 tab PO QD | H3: The insert says ≥71 kg 5 tablets 「可考慮」 and to follow the TW CDC 結核病診治指引, which caps INH at 300 mg and RIF at 600 mg. Five tablets give RIF 750 and INH 375 mg, over that cap, and the hospital page drops the caveat. | I3: TW 仿單 Akurit-4/Akurit-3 §3.1 — https://mcp.fda.gov.tw/im_detail_1/%E8%A1%9B%E7%BD%B2%E8%97%A5%E8%BC%B8%E5%AD%97%E7%AC%AC025518%E8%99%9F | J3: Open
A4: 1211 | B4: Akurit-4 / Akurit-3 (TB fixed-dose combinations) (AKU02, AKU01) | C4: High | D4: Dosing – adult | F4: Add caveat to 5-tablet >70 kg dose: exceeds INH 300/RIF 600 mg max; follow TW CDC guideline. | G4: Body weight >70 kg: 5 tab PO QD, with no caveat. | H4: The 仿單 says ≥71 kg 5 tablets 「可考慮」, but refers dosing to the 疾管署結核病診治指引 and states the daily maximum of INH 300 mg and RIF 600 mg. 5 tablets delivers RIF 750 mg and INH 375 mg. | I4: Akurit-4/Akurit-3 仿單 §3.1 https://mcp.fda.gov.tw/im_detail_1/%E8%A1%9B%E7%BD%B2%E8%97%A5%E8%BC%B8%E5%AD%97%E7%AC%AC025518%E8%99%9F | J4: Open
A5: 1204 | B5: Akurit-4 / Akurit-3 (TB fixed-dose combinations) (AKU02, AKU01) | C5: High | D5: Dosing – renal/dialysis | F5: Fill renal/hepatic fields: FDC unsuitable at CrCl<30/HD (EMB adjustment); contraindicated in acute liver disease. | G5: AKU01: renal field blank, and the adjacent hepatic field reads 'There are no dosage adjustments provided in the manufacturer's labeling; use with caution.' AKU02: both renal and hepatic fields are blank. | H5: Both inserts state that ethambutol must be reduced by serum level in renal impairment, so the fixed tablet is unsuitable at CrCl <30 or on HD. They also contraindicate acute liver disease, and Akurit-3 contraindicates severe hepatic impairment. | I5: TW 仿單 Akurit-3 §5.1 Ethambutol and §4 — https://mcp.fda.gov.tw/im_detail_1/%E8%A1%9B%E7%BD%B2%E8%97%A5%E8%BC%B8%E5%AD%97%E7%AC%AC025519%E8%99%9F; US ethambutol label PRECAUTIONS | J5: Open
A6: 1212 | B6: Akurit-4 / Akurit-3 (TB fixed-dose combinations) (AKU02, AKU01) | C6: High | D6: Dosing – renal/dialysis | F6: State FDC unsuitable for CrCl<30/HD; use single agents thrice weekly; add severe hepatic impairment contraindication. | G6: AKU01: 'There are no dosage adjustments provided in the manufacturer's labeling; use with caution.' AKU02: renal field empty. | H6: Both inserts §5.1 say ethambutol must be reduced according to serum levels in renal impairment. The FDC cannot be adjusted, so CrCl <30 or HD needs single agents (UK EMB SmPC §4.2: 15–25 mg/kg 3×/week; ATS 2016: PZA/EMB thrice weekly after HD). The Akurit-3 insert also contraindicates use in severe hepatic impairment. | I6: Akurit-3 仿單 §4, §5.1 https://mcp.fda.gov.tw/im_detail_1/%E8%A1%9B%E7%BD%B2%E8%97%A5%E8%BC%B8%E5%AD%97%E7%AC%AC025519%E8%99%9F ; UK Ethambutol SmPC §4.2 https://www.medicines.org.uk/emc/product/14174/smpc | J6: Open
A7: 1199 | B7: Akurit-4 / Akurit-3 (TB fixed-dose combinations) (AKU02, AKU01) | C7: High | D7: Drug interaction | E7: Interaction list incomplete | F7: Add contraindicated fosamprenavir, cabotegravir, fostemsavir, lenacapavir, praziquantel, lurasidone; cite ARV label source for rilpivirine/EVG. | G7: Concomitant atazanavir, darunavir, saquinavir, tipranavir, rilpivirine or elvitegravir/cobicistat | H7: The US rifampin label contraindicates atazanavir, darunavir, fosamprenavir, saquinavir, tipranavir, ritonavir-boosted saquinavir, cabotegravir, fostemsavir, lenacapavir (Sunlenca), praziquantel and lurasidone. UK SmPC adds sofosbuvir, daclatasvir, telaprevir and jaundice. The hospital list leaves out fosamprenavir, cabotegravir, fostemsavir, lenacapavir, praziquantel and lurasidone. Rilpivirine and EVG/c are not in the rifampin label, although their own labels contraindicate rifampin. | I7: US rifampin label CONTRAINDICATIONS — https://dailymed.nlm.nih.gov/dailymed/drugInfo.cfm?setid=50f706f9-5003-4e15-bece-85b6213b1f5c; UK Rifater SmPC 4.3 — https://www.medicines.org.uk/emc/product/1596/smpc | J7: Open
A8: 1208 | B8: Akurit-4 / Akurit-3 (TB fixed-dose combinations) (AKU02, AKU01) | C8: High | D8: Drug interaction | E8: Interaction list incomplete | F8: Expand rifampin contraindicated list with fosamprenavir, cabotegravir, fostemsavir, lenacapavir, praziquantel, lurasidone, sofosbuvir etc. | G8: Lists concomitant atazanavir, darunavir, saquinavir, tipranavir, rilpivirine or elvitegravir/cobicistat. | H8: The list is incomplete compared with the rifampin labels. The US label also contraindicates fosamprenavir, cabotegravir, fostemsavir, lenacapavir, praziquantel and lurasidone, plus saquinavir/ritonavir for hepatotoxicity. The UK Rifater SmPC adds sofosbuvir, daclatasvir and telaprevir. Rilpivirine and elvitegravir/cobicistat are not in the rifampin label contraindications (they come from the ARV labels). | I8: US rifampin label, Contraindications https://dailymed.nlm.nih.gov/dailymed/drugInfo.cfm?setid=50f706f9-5003-4e15-bece-85b6213b1f5c ; UK Rifater SmPC §4.3 https://www.medicines.org.uk/emc/product/1596/smpc | J8: Open
A9: 223 | B9: Amikacin (AMI12) | C9: High | D9: Dosing – adult | F9: State label max 15 mg/kg/day (≤1.5 g/day); mark higher/intrathecal regimens off-label with citations | G9: Bloodstream infection IV 15–30 mg/kg once daily; CF 30–35 mg/kg once daily; intraventricular/intrathecal 5–50 mg/day; other off-label regimens | H9: US: total daily dose ≤15 mg/kg/day in 2–3 doses; heavy patients ≤1.5 g/day. UK: 15 mg/kg/day (once daily only if CrCl ≥50), ≤1.5 g/day. TW (stocked product): 7.5–15 mg/kg/day ÷2, ≤1.5 g/day. No label gives an intrathecal dose; the UK SmPC mentions only 0.25% irrigation of the cerebral ventricles. | I9: US D&A; UK SmPC 4.2; Taiwan insert 3.1 – https://mcp.fda.gov.tw/im_detail_1/%E8%A1%9B%E7%BD%B2%E8%97%A5%E8%A3%BD%E5%AD%97%E7%AC%AC024198%E8%99%9F | J9: Open
A10: 229 | B10: Amikacin (AMI12) | C10: High | D10: Dosing – adult | F10: Cap at label 15 mg/kg/day; mark 15–35 mg/kg regimens off-label with citations | G10: Bloodstream infection, and sepsis/septic shock: IV 15 to 30 mg/kg once daily. HAP/VAP and plague: 15–20 mg/kg once daily. CF: 30–35 mg/kg once daily. | H10: US: total daily dose must not exceed 15 mg/kg/day, and heavier patients ≤1.5 g/day. UK: 15 mg/kg/day, ≤1.5 g/day. TW insert: 7.5–15 mg/kg/day ÷ bid; life-threatening or Pseudomonas up to 500 mg q8h, ≤1.5 g/day. Doses above this are off-label and need a guideline or PubMed source (e.g. Taccone 2010, PMID 20370907, for ≥25 mg/kg in septic shock). | I10: US label DOSAGE AND ADMINISTRATION; UK SmPC 4.2; TW insert 3.1, https://mcp.fda.gov.tw/im_detail_1/%E8%A1%9B%E7%BD%B2%E8%97%A5%E8%A3%BD%E5%AD%97%E7%AC%AC024198%E8%99%9F | J10: Open
A11: 231 | B11: Amikacin (AMI12) | C11: High | D11: Dosing – adult | F11: Add limits: high-dose 500 mg q8h max 1.5 g/day, ≤10 days, total course ≤15 g (TW/UK); reassess beyond 10 days | G11: No maximum daily dose, treatment duration, or total-course limit stated. | H11: TW insert 3.1 and UK SmPC 4.2: escalated regimen (500 mg q8h) ≤1.5 g/day, ≤10 days, total ≤15 g. US: usual 7–10 days; reassess if >10 days; safety >14 days not established. | I11: TW insert 3.1; UK SmPC 4.2; US label DOSAGE AND ADMINISTRATION and WARNINGS box | J11: Open
A12: 224 | B12: Amikacin (AMI12) | C12: High | D12: Dosing – renal/dialysis | E12: Renal table outdated | F12: Replace unsourced GFR/CRRT table with label method or cite source; reconcile CRRT with Notion | G12: GFR 30–50: 5–7.5 mg/kg q12–18h; GFR 10–29: q18–24h; GFR <10: q48–72h; HD/PD 5 mg/kg then redose by level; CRRT 7.5 mg/kg q12h | H12: No label has GFR tiers or CRRT dosing. US: 7.5 mg/kg every (SCr × 9) h, or 7.5 mg/kg LD then reduced q12h dose in proportion to CrCl; neither method during dialysis. UK: same methods, and no once-daily total dose if CrCl <50. TW insert: no renal table. The hospital CRRT dose (7.5 mg/kg q12h) also disagrees with the Notion CRRT entry (LD 10 mg/kg then TDM). Both need a guideline or PubMed source. | I12: US D&A renal sections – https://dailymed.nlm.nih.gov/dailymed/drugInfo.cfm?setid=f260ff2a-76a0-4672-9516-91c344b67890; UK SmPC 4.2 | J12: Open
A13: 230 | B13: Amikacin (AMI12) | C13: High | D13: Dosing – renal/dialysis | E13: Renal table outdated | F13: Replace pediatric-unit GFR table with adult label renal method; CRRT per evidence with TDM | G13: GFR 30–50 mL/min/1.73 m²: 5–7.5 mg/kg q12–18h; GFR 10–29: q18–24h; GFR <10: q48–72h; IHD 5 mg/kg, redose by level; CRRT 7.5 mg/kg q12h. This sits right after the paediatric section, and the units (per 1.73 m²) suggest a paediatric table shown as the general renal adjustment. | H13: No label gives GFR tiers or CRRT dosing. US label (fallback, since the TW insert has none): 7.5 mg/kg every SCr×9 h, or a 7.5 mg/kg loading dose then reduced q12h doses in proportion to CrCl; neither method during dialysis. UK SmPC: no once-daily dosing if CrCl <50. CRRT evidence (Roger 2016, PMID 27270279) supports 25 mg/kg about q48h with TDM, not 7.5 mg/kg q12h. | I13: US label Impaired Renal Function sections; UK SmPC 4.2; Roger C 2016, https://pubmed.ncbi.nlm.nih.gov/27270279/ | J13: Open
A14: 235 | B14: AmoClav (Amoxicillin/clavulanate) (AMO04, AMO08) | C14: High | D14: Dosing – adult | F14: Remove q6h option: 1.2 g q8h only (max 600 mg clavulanate/day); use other IV amoxicillin if more needed | G14: 1.2 g every 8 hours; in severe infections, administer every 6 hours | H14: 1000 mg/200 mg every 8 hours only. This product delivers at most 3000 mg amoxicillin + 600 mg clavulanate a day; if more amoxicillin is needed, use an alternative IV formulation. q6h would give 800 mg/day clavulanate. | I14: UK SmPC 4.2 — https://www.medicines.org.uk/emc/product/7211/smpc | J14: Open
A15: 236 | B15: AmoClav (Amoxicillin/clavulanate) (AMO04, AMO08) | C15: High | D15: Dosing – adult | F15: Fix prophylaxis: <1 h single 1.2–2.2 g at induction; >1 h up to 3 doses total in 24 h | G15: 1.2 g at induction of anesthesia for procedures 1 hour, may administer up to 2-3 additional doses in 24 hours (the < or > sign is missing) | H15: Procedures <1 h: 1000/200 to 2000/200 mg at induction. Procedures >1 h: same at induction, with up to 3 doses of 1000/200 mg in 24 hours (3 in total, not 2–3 additional). | I15: UK SmPC 4.2 — https://www.medicines.org.uk/emc/product/7211/smpc | J15: Open
A16: 246 | B16: AmoClav (Amoxicillin/clavulanate) (AMO04, AMO08) | C16: High | D16: Dosing – adult | F16: Remove q6h option: 1.2 g q8h only (max 600 mg clavulanate/day) | G16: 1.2 g every 8 hours; in severe infections, administer every 6 hours | H16: 1000/200 mg every 8 hours only. The vial is designed for at most 3000 mg amoxicillin + 600 mg clavulanate a day (q6h gives 800 mg clavulanate). If more amoxicillin is needed, use an alternative IV formulation. | I16: UK SmPC §4.2, https://www.medicines.org.uk/emc/product/7211/smpc | J16: Open
A17: 247 | B17: AmoClav (Amoxicillin/clavulanate) (AMO04, AMO08) | C17: High | D17: Dosing – adult | F17: Restore '<'/'>' and state max 3 doses total in 24 h for procedures >1 h | G17: 1.2 g at induction of anesthesia for procedures [sign missing] 1 hour, may administer up to 2-3 additional doses in 24 hours | H17: Procedures <1 h: 1000/200–2000/200 mg at induction. Procedures >1 h: same, with up to 3 doses of 1000/200 mg in 24 h in total. The '<'/'>' sign is lost in the hospital text, and '2-3 additional doses' could exceed 3 doses in total. | I17: UK SmPC §4.2, https://www.medicines.org.uk/emc/product/7211/smpc | J17: Open
A18: 237 | B18: AmoClav (Amoxicillin/clavulanate) (AMO04, AMO08) | C18: High | D18: Dosing – pediatric | F18: Pediatric <40 kg: ≥3 mo 30 mg/kg q8h; <3 mo or <4 kg 30 mg/kg q12h infusion; remove q6h and titration | G18: 3 months to 12 years: 30 mg/kg every 8 hours; in severe infections, administer every 6 hours. 30 mg/kg every 12 hours; then titrate to every 8 hours (no age/weight condition). | H18: Children <40 kg (weight-based, not 'to 12 years'): ≥3 months 25/5 mg/kg (30 mg/kg combined) q8h. Children <3 months or <4 kg: 25/5 mg/kg q12h, infusion only. There is no q6h option and no 'titrate to q8h' step. The pediatric q6h-in-severe-infection line was not in the source brief; I found it on the live page. | I18: UK SmPC 4.2 Paediatric population — https://www.medicines.org.uk/emc/product/7211/smpc | J18: Open
A19: 248 | B19: AmoClav (Amoxicillin/clavulanate) (AMO04, AMO08) | C19: High | D19: Dosing – pediatric | F19: Weight-based <40 kg dosing; no q6h; q12h only for <3 mo or <4 kg by infusion | G19: 3 months to 12 years: 30 mg/kg every 8 hours; in severe infections every 6 hours / 30 mg/kg every 12 hours; then titrate to every 8 hours | H19: Children <40 kg: ≥3 months, 25/5 mg/kg (=30 mg/kg combined) q8h; <3 months or <4 kg, 25/5 mg/kg q12h by infusion only. No q6h regimen. The q12h line in the hospital entry has no age or weight condition, and the limit is weight-based (<40 kg), not 12 years. | I19: UK SmPC §4.2 Paediatric population and Method of administration, https://www.medicines.org.uk/emc/product/7211/smpc | J19: Open
A20: 238 | B20: AmoClav (Amoxicillin/clavulanate) (AMO04, AMO08) | C20: High | D20: Dosing – renal/dialysis | E20: Renal table outdated | F20: HD: 1.2 g once, then 600 mg q24h plus 600 mg after dialysis; remove q12h option; use combined units | G20: 1 g followed by 500 mg every 12 to 24 hours; if utilizing a 24-hour interval, administer dose after dialysis or give an additional 500 mg after dialysis (units switch from 1.2 g product to amoxicillin-only mg) | H20: 1000/200 mg (1.2 g) initially, then 500/100 mg (600 mg) every 24 h, plus 500/100 mg at the end of dialysis. No q12h option. | I20: UK SmPC 4.2 Renal impairment — https://www.medicines.org.uk/emc/product/7211/smpc | J20: Open
A21: 239 | B21: AmoClav (Amoxicillin/clavulanate) (AMO04, AMO08) | C21: High | D21: Dosing – renal/dialysis | E21: Renal table outdated | F21: Remove unsupported PD q12h regimen; no label PD dose (CrCl <10 maintenance is 600 mg q24h) | G21: 1 g followed by 500 mg every 12 hours | H21: No peritoneal dialysis dose in the UK SmPC or US label. For CrCl <10 the SmPC gives 600 mg q24h maintenance, so a q12h PD regimen is unsupported. | I21: UK SmPC 4.2 — https://www.medicines.org.uk/emc/product/7211/smpc; US label 2.6 — https://dailymed.nlm.nih.gov/dailymed/drugInfo.cfm?setid=80bef3fd-4f6f-4190-8865-9ac46c8947a3 | J21: Open
A22: 240 | B22: AmoClav (Amoxicillin/clavulanate) (AMO04, AMO08) | C22: High | D22: Dosing – renal/dialysis | F22: Escape '<' in HTML so CrCl <10 band (1.2 g then 600 mg q24h) displays | G22: Rendered page shows only '3. CrCl' followed by '4. Hemodialysis'. The unescaped '<' cuts the text off; it reads in full only in the raw source ('CrCl <10 mL/min: 1.2 g followed by 600 mg every 24 hours'). | H22: The dose itself matches the SmPC (1.2 g, then 600 mg q24h). The defect is HTML escaping: the CrCl <10 line is invisible to users. | I22: UK SmPC 4.2 — https://www.medicines.org.uk/emc/product/7211/smpc | J22: Open
A23: 249 | B23: AmoClav (Amoxicillin/clavulanate) (AMO04, AMO08) | C23: High | D23: Dosing – renal/dialysis | E23: Renal table outdated | F23: HD: 1.2 g once, then 600 mg q24h plus 600 mg after dialysis; no q12h | G23: 1 g followed by 500 mg every 12 to 24 hours; if 24-hour interval, dose after dialysis or extra 500 mg after dialysis | H23: 1000/200 mg once, then 500/100 mg every 24 h, plus 500/100 mg at the end of dialysis. Units should be 1.2 g/600 mg to match the combined-strength convention used elsewhere. The SmPC gives no q12h option for HD. | I23: UK SmPC §4.2 Renal impairment, https://www.medicines.org.uk/emc/product/7211/smpc | J23: Open
A24: 250 | B24: AmoClav (Amoxicillin/clavulanate) (AMO04, AMO08) | C24: High | D24: Dosing – renal/dialysis | E24: Renal table outdated | F24: Remove PD 500 mg q12h regimen; no label support | G24: 1 g followed by 500 mg every 12 hours | H24: No PD regimen in the UK SmPC or the US label | I24: UK SmPC §4.2, https://www.medicines.org.uk/emc/product/7211/smpc | J24: Open
A25: 251 | B25: AmoClav (Amoxicillin/clavulanate) (AMO04, AMO08) | C25: High | D25: Dosing – renal/dialysis | F25: Escape '<' as &lt; so CrCl <10 line renders | G25: Rendered page shows '3. CrCl' with the text cut off. The raw HTML has 'CrCl <10 mL/min: 1.2 g followed by 600 mg every 24 hours'; the unescaped '<' breaks rendering. | H25: CrCl <10: 1000/200 mg once, then 500/100 mg q24h (the content is correct once shown; the HTML needs '&lt;') | I25: UK SmPC §4.2, https://www.medicines.org.uk/emc/product/7211/smpc | J25: Open
A26: 581 | B26: Amoxicillin (AMO02) | C26: High | D26: Dosing – renal/dialysis | E26: Renal table outdated | F26: Restore GFR <10 label; set 250-500 mg q24h (US), max 500 mg/day (UK); remove q12h | G26: The row after '10-30' has no GFR label: '250 to 500 mg every 12 to 24 hours / 500 mg every 12 to 24 hours / 500 mg every 12 hours'. | H26: Presumably this row is GFR <10, and the US label gives 250–500 mg q24h there, not q12–24h. The UK SmPC gives a maximum of 500 mg/day. Neither label supports the 'every 12 hours' column. | I26: US FDA label §2.5 Table 2 — https://dailymed.nlm.nih.gov/dailymed/drugInfo.cfm?setid=9b3ab9ea-caee-4186-9068-43ca527c098d; UK SmPC §4.2 — https://www.medicines.org.uk/emc/product/10637/smpc | J26: Open
A27: 582 | B27: Amoxicillin (AMO02) | C27: High | D27: Dosing – renal/dialysis | E27: Renal table outdated | F27: GFR 10-30: change 1 g q12h to 250-500 mg q12h (max 500 mg bid) | G27: 1 g every 12 hours | H27: US: 250–500 mg every 12 hours. UK: maximum 500 mg twice daily. 1 g q12h is twice the labelled maximum. | I27: US FDA label §2.5 Table 2 — https://dailymed.nlm.nih.gov/dailymed/drugInfo.cfm?setid=9b3ab9ea-caee-4186-9068-43ca527c098d; UK SmPC §4.2 Renal impairment — https://www.medicines.org.uk/emc/product/10637/smpc | J27: Open
A28: 583 | B28: Amoxicillin (AMO02) | C28: High | D28: Dosing – renal/dialysis | E28: Renal table outdated | F28: HD: 250-500 mg q24h plus supplemental dose during/after HD; remove q12h options | G28: 250 to 500 mg every 12 to 24 hours / 500 mg every 12 to 24 hours / 500 mg every 12 hours | H28: US: 250–500 mg every 24 h, plus an extra dose during and at the end of dialysis. UK: 500 mg every 24 h, plus 500 mg before and 500 mg after HD. Neither label has a q12h option, and the hospital row omits the supplemental dose. The source brief did not mention this discrepancy. | I28: US FDA label §2.5 — https://dailymed.nlm.nih.gov/dailymed/drugInfo.cfm?setid=9b3ab9ea-caee-4186-9068-43ca527c098d; UK SmPC §4.2 Haemodialysis — https://www.medicines.org.uk/emc/product/10637/smpc | J28: Open
A29: 584 | B29: Amoxicillin (AMO02) | C29: High | D29: Dosing – renal/dialysis | E29: Renal table outdated | F29: PD: cap at 500 mg/day (UK SmPC); remove 500 mg q12h | G29: 250 to 500 mg every 12 hours / 500 mg every 12 hours / 500 mg every 12 hours | H29: UK: maximum 500 mg/day. The US label has no PD dose, so the PD row conflicts with the UK SmPC only; 500 mg q12h is 1 g/day. | I29: UK SmPC §4.2 'In patients receiving peritoneal dialysis Amoxicillin maximum 500 mg/day' — https://www.medicines.org.uk/emc/product/10637/smpc | J29: Open
A30: 591 | B30: Amoxicillin (AMO02) | C30: High | D30: Dosing – renal/dialysis | E30: Renal table outdated | F30: Fix missing '<10' row label (HTML escape); set 250-500 mg q24h, max 500 mg/day | G30: Row with no GFR label: '250 to 500 mg every 12 to 24 hours / 500 mg every 12 to 24 hours / 500 mg every 12 hours' (presumably GFR <10; label probably lost to unescaped '<' in HTML) | H30: GFR <10: 250–500 mg q24h (US); max 500 mg/day (UK). q12h and q12–24h both exceed the label maximum. | I30: US label §2.5 Table 2 — https://dailymed.nlm.nih.gov/dailymed/drugInfo.cfm?setid=9b3ab9ea-caee-4186-9068-43ca527c098d; UK SmPC §4.2 — https://www.medicines.org.uk/emc/product/10637/smpc | J30: Open
A31: 592 | B31: Amoxicillin (AMO02) | C31: High | D31: Dosing – renal/dialysis | E31: Renal table outdated | F31: GFR 10-30: change 1 g q12h to 250-500 mg q12h | G31: 1 g every 12 hours | H31: US: 250–500 mg q12h; UK: maximum 500 mg twice daily | I31: US label §2.5 Table 2; UK SmPC §4.2 renal table | J31: Open
A32: 593 | B32: Amoxicillin (AMO02) | C32: High | D32: Dosing – renal/dialysis | E32: Renal table outdated | F32: HD: 250-500 mg q24h plus supplemental dose with HD; remove q12h | G32: 250–500 mg q12–24h / 500 mg q12–24h / 500 mg q12h; no supplemental dose | H32: US: 250–500 mg q24h + extra dose during and at end of HD. UK: 500 mg q24h + 500 mg before and 500 mg after HD. No q12h option. | I32: US label §2.5 Table 2; UK SmPC §4.2 haemodialysis | J32: Open
A33: 594 | B33: Amoxicillin (AMO02) | C33: High | D33: Dosing – renal/dialysis | E33: Renal table outdated | F33: PD: max 500 mg/day (UK SmPC); remove q12h regimens | G33: 250–500 mg q12h / 500 mg q12h / 500 mg q12h (up to 1 g/day) | H33: UK: maximum 500 mg/day. No US PD dose. | I33: UK SmPC §4.2 peritoneal dialysis — https://www.medicines.org.uk/emc/product/10637/smpc | J33: Open
A34: 576 | B34: Ampolin (Ampicillin) (AMP01) | C34: High | D34: Dosing – adult | F34: Add label doses; label 2 g q4h and 300-400 mg/kg/day as guideline with citation; 400 mg/kg/day exceeds labels | G34: Adults 2 g q4h (enterococcal/Listeria bacteremia, endocarditis, meningitis); 1–2 g q4–6h for enterococcal cUTI; children 50–200 mg/kg/day (max 8 g/day), 300–400 mg/kg/day (max 12 g/day) for meningitis/endocarditis. No citation, and no label doses shown. | H34: The stocked product's insert gives 250–500 mg q6h (or 2–4×/day IM), gonococcal urethritis 500 mg q12h, meningitis 8–14 g/day adults and 100–200 mg/kg/day children. US: 250–500 mg q6h; meningitis/septicemia 150–200 mg/kg/day q3–4h. UK: 500 mg 4–6×/day; meningitis 2 g q6h. The 2 g q4h and 300–400 mg/kg/day regimens are guideline (IDSA/AHA/ESC) doses, not label doses, and should be labelled and cited as such. 400 mg/kg/day exceeds every label. | I34: Ampolin 仿單 用法用量 https://mcp.fda.gov.tw/insert/pdfcasefile/i_f87fe441-fe10-4930-90d7-250bb0fcbf57; DailyMed DOSAGE AND ADMINISTRATION https://dailymed.nlm.nih.gov/dailymed/drugInfo.cfm?setid=64a04e8c-8f78-46b3-8f45-56ef225a4f74; UK SmPC 4.2 https://www.medicines.org.uk/emc/product/12892/smpc | J34: Open
A35: 568 | B35: Ampolin (Ampicillin) (AMP01) | C35: High | D35: Dosing – pediatric | F35: Clarify cIAI max 2,000 mg as per dose; note no label cIAI pediatric dose | G35: 200 mg/kg/day divided every 6 hours; maximum 2,000 mg | H35: No label gives a paediatric cIAI dose. 'Maximum 2,000 mg' does not say whether it is per dose or per day; read as per day it caps a 200 mg/kg/day regimen at 10 kg body weight. It looks like a per-dose cap written ambiguously. The label paediatric doses are 25-50 mg/kg/day (RTI/soft tissue), 50 mg/kg/day (GI/GU) and 150-200 mg/kg/day (meningitis/septicemia). | I35: DailyMed ampicillin DOSAGE AND ADMINISTRATION https://dailymed.nlm.nih.gov/dailymed/drugInfo.cfm?setid=3b683547-48ac-48ca-8fd4-6866fd17be34 | J35: Open
A36: 569 | B36: Ampolin (Ampicillin) (AMP01) | C36: High | D36: Dosing – pediatric | F36: Replace pediatric doses with label ranges; add US neonatal GA/PNA table; flag >200 mg/kg/day as off-label | G36: 50-200 mg/kg/day q6h (max 8 g/day); 300-400 mg/kg/day (max 12 g/day) for meningitis; IE 200-300 mg/kg/day | H36: These figures and maximums are not in the TW insert (meningitis 100-200 mg/kg/day; general 25-60 mg/kg/day) or the US label (150-200 mg/kg/day; neonatal table by GA/PNA). The neonatal dosing table in the US label is missing from the hospital page. | I36: Taiwan insert https://mcp.fda.gov.tw/insert/pdfcasefile/i_f87fe441-fe10-4930-90d7-250bb0fcbf57; DailyMed ampicillin TABLE 1 https://dailymed.nlm.nih.gov/dailymed/drugInfo.cfm?setid=3b683547-48ac-48ca-8fd4-6866fd17be34 | J36: Open
A37: 575 | B37: Ampolin (Ampicillin) (AMP01) | C37: High | D37: Dosing – pediatric | F37: Specify cIAI cap as 2,000 mg/dose; note not label-derived | G37: 200 mg/kg/day divided every 6 hours; maximum 2,000 mg | H37: No label gives a pediatric cIAI dose or this cap. As written, 'maximum 2,000 mg' reads as a daily cap, which would contradict 200 mg/kg/day for any child over 10 kg. It is presumably a per-dose cap and should say '/dose'. | I37: DailyMed ampicillin DOSAGE AND ADMINISTRATION (no cIAI dose) https://dailymed.nlm.nih.gov/dailymed/drugInfo.cfm?setid=3b683547-48ac-48ca-8fd4-6866fd17be34; Ampolin 仿單 https://mcp.fda.gov.tw/insert/pdfcasefile/i_f87fe441-fe10-4930-90d7-250bb0fcbf57 | J37: Open
A38: 570 | B38: Ampolin (Ampicillin) (AMP01) | C38: High | D38: Dosing – renal/dialysis | E38: Renal table outdated | F38: Cite renal intervals source; add post-HD supplemental dose (UK SmPC) | G38: CrCl 10-50: interval q6-12h; CrCl <10: interval q12-16h | H38: The TW insert and US labels have no CrCl table. The UK SmPC says only that for CrCl <10 the dose should be reduced or the interval extended, with an extra dose after dialysis. The hospital's intervals cite no source, and the page says nothing about dosing after HD. | I38: UK SmPC 4.2 https://www.medicines.org.uk/emc/product/12892/smpc; DailyMed ampicillin OVERDOSAGE https://dailymed.nlm.nih.gov/dailymed/drugInfo.cfm?setid=3b683547-48ac-48ca-8fd4-6866fd17be34 | J38: Open
A39: 577 | B39: Ampolin (Ampicillin) (AMP01) | C39: High | D39: Dosing – renal/dialysis | E39: Renal table outdated | F39: Revise renal intervals (q12h CrCl 7-30, q24h post-HD in ESRD per Blum 1989); add HD/PD/CRRT guidance with sources | G39: CrCl 10–50: q6–12h; CrCl <10: q12–16h (uncited) | H39: No label has a CrCl table: the TW insert has no renal section, the US label has none, and the UK SmPC only says CrCl <10 → reduce dose or extend interval plus a post-dialysis dose. The available PK study (Blum 1989, ampicillin 2 g) supports q12h at CrCl 7–30 and q24h after HD for ESRD, longer than the hospital's q12–16h. The hospital page also gives no HD, PD or CRRT guidance. The label says ampicillin is removed by HD, not PD. | I39: UK SmPC 4.2 Renal Impairment https://www.medicines.org.uk/emc/product/12892/smpc; DailyMed OVERDOSAGE https://dailymed.nlm.nih.gov/dailymed/drugInfo.cfm?setid=3b683547-48ac-48ca-8fd4-6866fd17be34; Blum RA 1989 PMID 2817847 https://pubmed.ncbi.nlm.nih.gov/2817847/ | J39: Open
A40: 269 | B40: Antifect (Cefepime) (ANT10) | C40: High | D40: Administration/compatibility | F40: Infusion fluids: NS, D5W/D10W, D5NS, M/6 lactate, LR with D5; SWFI for reconstitution only, not plain LR | G40: 稀釋溶液：NS、D5W、SWFI、LR (仿單) | H40: TW insert/FDA infusion fluids: 0.9% NaCl, 5% and 10% dextrose, M/6 sodium lactate, D5NS, lactated Ringer's WITH 5% dextrose (not plain LR). Sterile water is listed only for reconstitution, not as an infusion diluent. | I40: Taiwan Antifect insert §3.2 相容性及安定性 — https://mcp.fda.gov.tw/im_detail_1/%E8%A1%9B%E7%BD%B2%E8%97%A5%E8%A3%BD%E5%AD%97%E7%AC%AC047983%E8%99%9F ; US FDA label §2.4, §2.6 | J40: Open
...

Sheet Recurring patterns
A1: Pattern | B1: What it means | C1: Rows (All issues) | D1: of which High
A2: Renal table outdated | B2: Renal dose bands do not match the current label (CrCl bands, HD/CRRT rows missing or different). | C2: =COUNTIF('All issues'!$E$2:$E$1465,A2) | D2: =COUNTIFS('All issues'!$E$2:$E$1465,A2,'All issues'!$C$2:$C$1465,"High")
A3: FDA letter category | B3: Pregnancy shown as an FDA letter (A/B/C/D/X). The FDA retired these in 2015 (PLLR); replace with the label narrative. | C3: =COUNTIF('All issues'!$E$2:$E$1465,A3) | D3: =COUNTIFS('All issues'!$E$2:$E$1465,A3,'All issues'!$C$2:$C$1465,"High")
A4: LactMed outdated | B4: Breastfeeding text is older or more restrictive than current LactMed. | C4: =COUNTIF('All issues'!$E$2:$E$1465,A4) | D4: =COUNTIFS('All issues'!$E$2:$E$1465,A4,'All issues'!$C$2:$C$1465,"High")
A5: Missing SCAR (SJS/TEN/DRESS) | B5: Severe cutaneous adverse reactions listed in the label are missing. | C5: =COUNTIF('All issues'!$E$2:$E$1465,A5) | D5: =COUNTIFS('All issues'!$E$2:$E$1465,A5,'All issues'!$C$2:$C$1465,"High")
A6: Interaction list incomplete | B6: Interaction or contraindicated co-medication list is shorter than the label. | C6: =COUNTIF('All issues'!$E$2:$E$1465,A6) | D6: =COUNTIFS('All issues'!$E$2:$E$1465,A6,'All issues'!$C$2:$C$1465,"High")
A7: Missing boxed warning | B7: A US boxed warning is not mentioned. | C7: =COUNTIF('All issues'!$E$2:$E$1465,A7) | D7: =COUNTIFS('All issues'!$E$2:$E$1465,A7,'All issues'!$C$2:$C$1465,"High")
A8: Missing C. difficile warning | B8: The C. difficile-associated diarrhoea warning in the label is missing. | C8: =COUNTIF('All issues'!$E$2:$E$1465,A8) | D8: =COUNTIFS('All issues'!$E$2:$E$1465,A8,'All issues'!$C$2:$C$1465,"High")
A9: Tip | B9: Fixing these as one batch across all drugs is faster than drug by drug.

Sheet By drug
A1: Drug (hospital code) | B1: High | C1: Medium | D1: Low | E1: Total
A2: Akurit-4 / Akurit-3 (TB fixed-dose combinations) (AKU02, AKU01) | B2: =COUNTIFS('All issues'!$B$2:$B$1465,A2,'All issues'!$C$2:$C$1465,"High") | C2: =COUNTIFS('All issues'!$B$2:$B$1465,A2,'All issues'!$C$2:$C$1465,"Medium") | D2: =COUNTIFS('All issues'!$B$2:$B$1465,A2,'All issues'!$C$2:$C$1465,"Low") | E2: =SUM(B2:D2)
A3: Amikacin (AMI12) | B3: =COUNTIFS('All issues'!$B$2:$B$1465,A3,'All issues'!$C$2:$C$1465,"High") | C3: =COUNTIFS('All issues'!$B$2:$B$1465,A3,'All issues'!$C$2:$C$1465,"Medium") | D3: =COUNTIFS('All issues'!$B$2:$B$1465,A3,'All issues'!$C$2:$C$1465,"Low") | E3: =SUM(B3:D3)
